Workbook

Sheet Directorio
A6: DIRECTORIO DE GERENCIAS Y COORDINACIONES
A7: Productos y Servicios Mr. Lana, S.A.P.I. de C.V. · Gerencia de Recursos Humanos
A9: Actualizado: 23 de julio de 2026
A11: NO. NOI | B11: NOMBRE DEL COLABORADOR | C11: SUCURSAL | D11: PUESTO | E11: CORREO INSTITUCIONAL | F11: NO. TELEFÓNICO
A12: ▎ SUCURSAL ATLACOMULCO | E12: =COUNTIF(C13:C14,"ATLACOMULCO")&" colaboradores" -> 2 colaboradores
A13: 624 | B13: ELIOT SERRANO SANCHEZ | C13: ATLACOMULCO | D13: SUBGERENTE | E13: eliot.serrano@mr-lana.com | F13: 712 225 6115
A14: 8 | B14: ANGELICA AZUCENA GONZALEZ | C14: ATLACOMULCO | D14: COORDINADORA | E14: angelica.granados@mr-lana.com | F14: 722 355 9570
A16: ▎ SUCURSAL ATLIXCO | E16: =COUNTIF(C17:C17,"ATLIXCO")&" colaboradores" -> 1 colaboradores
A17: 20 | B17: LUIS ANGEL LOPEZ RAMIREZ | C17: ATLIXCO | D17: GERENTE | E17: luis.lopez@mr-lana.com | F17: 2241510289
A18: 841 | B18: RAMSES LEONIDES ROJAS PEREZ | C18: ATLIXCO | D18: SUBGERENTE | E18: ramses.rojas@mr-lana.com | F18: 52 1 222 238 8497
A20: ▎ SUCURSAL CUERNAVACA | E20: =COUNTIF(C21:C22,"CUERNAVACA")&" colaboradores" -> 2 colaboradores
B21: JAIME VALVERDE ERIVES | C21: CUERNAVACA | D21: SUBGERENTE | E21: jaime.valverde@mr-lana.com | F21: 777 961 3528
A22: 54 | B22: MARIBEL DIAZ SUAREZ | C22: CUERNAVACA | D22: COORDINADORA | E22: maribel.diaz@mr-lana.com | F22: 777 632 5091
A24: ▎ SUCURSAL CÓRDOBA | E24: =COUNTIF(C25:C26,"CÓRDOBA")&" colaboradores" -> 2 colaboradores
A25: 36 | B25: RICARDO ROCHA MORA | C25: CÓRDOBA | D25: GERENTE | E25: ricardo.rocha@mr-lana.com | F25: 271 213 8711
A26: 43 | B26: HESIQUIO MARTINEZ ZUÑIGA | C26: CÓRDOBA | D26: SUBGERENTE | E26: hesiquio.martinez@mr-lana.com | F26: 271 342 8403
A28: ▎ SUCURSAL HUAMANTLA | E28: =COUNTIF(C29:C30,"HUAMANTLA")&" colaboradores" -> 2 colaboradores
A29: 833 | B29: JUAN ANGEL GONZALEZ RUIZ | C29: HUAMANTLA | D29: GERENTE | E29: juan.gonzalez@mr-lana.com | F29: 247 118 3176
A30: 644 | B30: ROSALINDA MARIBEL CUELLAR | C30: HUAMANTLA | D30: COORDINADORA | E30: rosalinda.cuellar@mr-lana.com | F30: SIN REGISTRO
A32: ▎ SUCURSAL IXTLAHUACA | E32: =COUNTIF(C33:C34,"IXTLAHUACA")&" colaboradores" -> 2 colaboradores
A33: 704 | B33: LUIS GARAY PEREZ | C33: IXTLAHUACA | D33: GERENTE | E33: luis.garay@mr-lana.com | F33: 7206656747
A34: 660 | B34: ANA LAURA SANCHEZ ALDAMA | C34: IXTLAHUACA | D34: COORDINADORA | E34: ana.sanchez@mr-lana.com | F34: 712 688 1615
A36: ▎ SUCURSAL MIACATLÁN | E36: =COUNTIF(C37:C38,"MIACATLÁN")&" colaboradores" -> 2 colaboradores
A37: 890 | B37: JOSE OMAR GONZALEZ HUERTA | C37: MIACATLÁN | D37: GERENTE | E37: jose.gonzalez@mr-lana.com
A38: 145 | B38: MONICA OCAMPO NIETO | C38: MIACATLÁN | D38: COORDINADORA | E38: monica.ocampo@mr-lana.com | F38: 737 373 54 86
A40: ▎ SUCURSAL ORIZABA | E40: =COUNTIF(C41:C43,"ORIZABA")&" colaboradores" -> 3 colaboradores
A41: 134 | B41: IVAN QUEVEDO LOPEZ | C41: ORIZABA | D41: GERENTE | E41: ivan.quevedo@mr-lana.com | F41: 272 207 7149
A42: 120 | B42: LIZETTE ALEJANDRA AGUILAR | C42: ORIZABA | D42: SUBGERENTE | E42: lizette.aguilar@mr-lana.com | F42: 2722331237
A43: 22 | B43: ALEJANDRA ROSAS JUAREZ | C43: ORIZABA | D43: COORDINADORA | E43: alejandra.rosas@mr-lana.com | F43: 272 104 2228
A45: ▎ SUCURSAL SAN LUIS POTOSÍ | E45: =COUNTIF(C47:C47,"SAN LUIS POTOSÍ")&" colaboradores" -> 1 colaboradores
B46: HUGO SAUL HERRERA RAFFUL | C46: SAN LUIS POTOSÍ | D46: SUBGERENTE | E46: hugo.herrera@mr-lana.com
A47: 149 | B47: MERCEDES RODRIGUEZ CAMPOS | C47: SAN LUIS POTOSÍ | D47: COORDINADORA | E47: mercedes.rodriguez@mr-lana.com | F47: 444 222 5854
A49: ▎ SUCURSAL TLAXCALA | E49: =COUNTIF(C51:C52,"TLAXCALA")&" colaboradores" -> 2 colaboradores
B50: ISAIAS FARIAS BONILLA | C50: TLAXCALA | D50: GERENTE | E50: isaias.farias@mr-lana.com
A51: 863 | B51: MARLEN RAZO SALDAÑA | C51: TLAXCALA | D51: SUBGERENTE | E51: marlen.razo@mr-lana.com | F51: SIN REGISTRO
A52: 728 | B52: MARICELA FLORES CABRERA | C52: TLAXCALA | D52: COORDINADORA | E52: maricela.flores@mr-lana.com | F52: 246 466 75 87
A54: ▎ SUCURSAL TULA | E54: =COUNTIF(C55:C56,"TULA")&" colaboradores" -> 2 colaboradores
A55: 179 | B55: MONICA ANA KAREN GARCIA | C55: TULA | D55: GERENTE REGIONAL | E55: monica.garcia@mr-lana.com | F55: 55 3938 9689
A56: 504 | B56: LIDIA MONTSERRAT JIMENEZ | C56: TULA | D56: GERENTE | E56: lidia.jimenez@mr-lana.com | F56: 5517053573
A57: 895 | B57: MARIA DEL CARMEN GODOY GONZAGA | C57: TULA | D57: COORDINADORA | E57: maria.godoy@mr-lana.com
...

Sheet Resumen
A2: RESUMEN EJECUTIVO · ESTRUCTURA DE MANDOS POR SUCURSAL
A3: Productos y Servicios Mr. Lana, S.A.P.I. de C.V. · Corte al 23 de julio de 2026
B7: =COUNTA(Directorio!B12:B56) -> 24 | C7: =SUMPRODUCT((Directorio!C12:C56<>"")/COUNTIF(Directorio!C12:C56,Directorio!C12:C56&"")) -> 11 | D7: =COUNTIF(Directorio!D12:D56,"GERENTE")+COUNTIF(Directorio!D12:D56,"GERENTE REGIONAL") -> 8 | E7: =COUNTIF(Directorio!D12:D56,"COORDINADO*") -> 8 | F7: =COUNTIF(Directorio!F12:F56,"SIN REGISTRO") -> 2
B8: COLABORADORES | C8: SUCURSALES | D8: GERENCIAS | E8: COORDINACIONES | F8: SIN TELÉFONO
B10: DISTRIBUCIÓN DE PLANTILLA POR SUCURSAL Y PUESTO
B11: SUCURSAL | C11: GERENTE REGIONAL | D11: GERENTE | E11: SUBGERENTE | F11: COORDINACIÓN | G11: TOTAL
B12: ATLACOMULCO | C12: =COUNTIFS(Directorio!$C$12:$C$56,$B12,Directorio!$D$12:$D$56,"GERENTE REGIONAL") -> 0 | D12: =COUNTIFS(Directorio!$C$12:$C$56,$B12,Directorio!$D$12:$D$56,"GERENTE") -> 0 | E12: =COUNTIFS(Directorio!$C$12:$C$56,$B12,Directorio!$D$12:$D$56,"SUBGERENTE") -> 1 | F12: =COUNTIFS(Directorio!$C$12:$C$56,$B12,Directorio!$D$12:$D$56,"COORDINADO*") -> 1 | G12: =SUM(C12:F12) -> 2
B13: ATLIXCO | C13: =COUNTIFS(Directorio!$C$12:$C$56,$B13,Directorio!$D$12:$D$56,"GERENTE REGIONAL") -> 0 | D13: =COUNTIFS(Directorio!$C$12:$C$56,$B13,Directorio!$D$12:$D$56,"GERENTE") -> 1 | E13: =COUNTIFS(Directorio!$C$12:$C$56,$B13,Directorio!$D$12:$D$56,"SUBGERENTE") -> 1 | F13: =COUNTIFS(Directorio!$C$12:$C$56,$B13,Directorio!$D$12:$D$56,"COORDINADO*") -> 0 | G13: =SUM(C13:F13) -> 2
B14: CUERNAVACA | C14: =COUNTIFS(Directorio!$C$12:$C$56,$B14,Directorio!$D$12:$D$56,"GERENTE REGIONAL") -> 0 | D14: =COUNTIFS(Directorio!$C$12:$C$56,$B14,Directorio!$D$12:$D$56,"GERENTE") -> 0 | E14: =COUNTIFS(Directorio!$C$12:$C$56,$B14,Directorio!$D$12:$D$56,"SUBGERENTE") -> 1 | F14: =COUNTIFS(Directorio!$C$12:$C$56,$B14,Directorio!$D$12:$D$56,"COORDINADO*") -> 1 | G14: =SUM(C14:F14) -> 2
B15: CÓRDOBA | C15: =COUNTIFS(Directorio!$C$12:$C$56,$B15,Directorio!$D$12:$D$56,"GERENTE REGIONAL") -> 0 | D15: =COUNTIFS(Directorio!$C$12:$C$56,$B15,Directorio!$D$12:$D$56,"GERENTE") -> 1 | E15: =COUNTIFS(Directorio!$C$12:$C$56,$B15,Directorio!$D$12:$D$56,"SUBGERENTE") -> 1 | F15: =COUNTIFS(Directorio!$C$12:$C$56,$B15,Directorio!$D$12:$D$56,"COORDINADO*") -> 0 | G15: =SUM(C15:F15) -> 2
B16: HUAMANTLA | C16: =COUNTIFS(Directorio!$C$12:$C$56,$B16,Directorio!$D$12:$D$56,"GERENTE REGIONAL") -> 0 | D16: =COUNTIFS(Directorio!$C$12:$C$56,$B16,Directorio!$D$12:$D$56,"GERENTE") -> 1 | E16: =COUNTIFS(Directorio!$C$12:$C$56,$B16,Directorio!$D$12:$D$56,"SUBGERENTE") -> 0 | F16: =COUNTIFS(Directorio!$C$12:$C$56,$B16,Directorio!$D$12:$D$56,"COORDINADO*") -> 1 | G16: =SUM(C16:F16) -> 2
B17: IXTLAHUACA | C17: =COUNTIFS(Directorio!$C$12:$C$56,$B17,Directorio!$D$12:$D$56,"GERENTE REGIONAL") -> 0 | D17: =COUNTIFS(Directorio!$C$12:$C$56,$B17,Directorio!$D$12:$D$56,"GERENTE") -> 1 | E17: =COUNTIFS(Directorio!$C$12:$C$56,$B17,Directorio!$D$12:$D$56,"SUBGERENTE") -> 0 | F17: =COUNTIFS(Directorio!$C$12:$C$56,$B17,Directorio!$D$12:$D$56,"COORDINADO*") -> 1 | G17: =SUM(C17:F17) -> 2
B18: MIACATLÁN | C18: =COUNTIFS(Directorio!$C$12:$C$56,$B18,Directorio!$D$12:$D$56,"GERENTE REGIONAL") -> 0 | D18: =COUNTIFS(Directorio!$C$12:$C$56,$B18,Directorio!$D$12:$D$56,"GERENTE") -> 1 | E18: =COUNTIFS(Directorio!$C$12:$C$56,$B18,Directorio!$D$12:$D$56,"SUBGERENTE") -> 0 | F18: =COUNTIFS(Directorio!$C$12:$C$56,$B18,Directorio!$D$12:$D$56,"COORDINADO*") -> 1 | G18: =SUM(C18:F18) -> 2
B19: ORIZABA | C19: =COUNTIFS(Directorio!$C$12:$C$56,$B19,Directorio!$D$12:$D$56,"GERENTE REGIONAL") -> 0 | D19: =COUNTIFS(Directorio!$C$12:$C$56,$B19,Directorio!$D$12:$D$56,"GERENTE") -> 1 | E19: =COUNTIFS(Directorio!$C$12:$C$56,$B19,Directorio!$D$12:$D$56,"SUBGERENTE") -> 1 | F19: =COUNTIFS(Directorio!$C$12:$C$56,$B19,Directorio!$D$12:$D$56,"COORDINADO*") -> 1 | G19: =SUM(C19:F19) -> 3
B20: SAN LUIS POTOSÍ | C20: =COUNTIFS(Directorio!$C$12:$C$56,$B20,Directorio!$D$12:$D$56,"GERENTE REGIONAL") -> 0 | D20: =COUNTIFS(Directorio!$C$12:$C$56,$B20,Directorio!$D$12:$D$56,"GERENTE") -> 0 | E20: =COUNTIFS(Directorio!$C$12:$C$56,$B20,Directorio!$D$12:$D$56,"SUBGERENTE") -> 1 | F20: =COUNTIFS(Directorio!$C$12:$C$56,$B20,Directorio!$D$12:$D$56,"COORDINADO*") -> 1 | G20: =SUM(C20:F20) -> 2
B21: TLAXCALA | C21: =COUNTIFS(Directorio!$C$12:$C$56,$B21,Directorio!$D$12:$D$56,"GERENTE REGIONAL") -> 0 | D21: =COUNTIFS(Directorio!$C$12:$C$56,$B21,Directorio!$D$12:$D$56,"GERENTE") -> 0 | E21: =COUNTIFS(Directorio!$C$12:$C$56,$B21,Directorio!$D$12:$D$56,"SUBGERENTE") -> 1 | F21: =COUNTIFS(Directorio!$C$12:$C$56,$B21,Directorio!$D$12:$D$56,"COORDINADO*") -> 1 | G21: =SUM(C21:F21) -> 2
B22: TULA | C22: =COUNTIFS(Directorio!$C$12:$C$56,$B22,Directorio!$D$12:$D$56,"GERENTE REGIONAL") -> 1 | D22: =COUNTIFS(Directorio!$C$12:$C$56,$B22,Directorio!$D$12:$D$56,"GERENTE") -> 1 | E22: =COUNTIFS(Directorio!$C$12:$C$56,$B22,Directorio!$D$12:$D$56,"SUBGERENTE") -> 0 | F22: =COUNTIFS(Directorio!$C$12:$C$56,$B22,Directorio!$D$12:$D$56,"COORDINADO*") -> 0 | G22: =SUM(C22:F22) -> 2
B23: TOTAL GENERAL | C23: =SUM(C12:C22) -> 1 | D23: =SUM(D12:D22) -> 7 | E23: =SUM(E12:E22) -> 7 | F23: =SUM(F12:F22) -> 8 | G23: =SUM(G12:G22) -> 23
B25: Semáforo: las celdas en rojo (0) señalan puestos de mando no cubiertos en la sucursal correspondiente; en verde, plaza ocupada.
B26: Todos los indicadores se calculan con fórmulas sobre la hoja DIRECTORIO; cualquier alta, baja o cambio se refleja de forma automática.
